WARNING 2025-04-05 19:46:05,141 crawler 41660 2696 开始爬取豆瓣
WARNING 2025-04-05 19:46:05,142 crawler 41660 2696 开始爬取豆瓣，类型: DOUBAN
ERROR 2025-04-05 19:46:05,174 crawler 41660 2696 爬取豆瓣出错: 'Spider not found: douban_spider'
ERROR 2025-04-05 19:46:05,177 crawler 41660 2696 Traceback (most recent call last):
  File "D:\Anaconda\envs\djangoLearn\Lib\site-packages\scrapy\spiderloader.py", line 89, in load
    return self._spiders[spider_name]
           ~~~~~~~~~~~~~^^^^^^^^^^^^^
KeyError: 'douban_spider'

During handling of the above exception, another exception occurred:

Traceback (most recent call last):
  File "D:\python_learn\CollectIp\CollectIp\ip_operator\services\crawler.py", line 126, in start_crawl_douban
    process.crawl('douban_spider', movie_name=movie_name)
  File "D:\Anaconda\envs\djangoLearn\Lib\site-packages\scrapy\crawler.py", line 332, in crawl
    crawler = self.create_crawler(crawler_or_spidercls)
              ^^^^^^^^^^^^^^^^^^^^^^^^^^^^^^^^^^^^^^^^^
  File "D:\Anaconda\envs\djangoLearn\Lib\site-packages\scrapy\crawler.py", line 368, in create_crawler
    return self._create_crawler(crawler_or_spidercls)
           ^^^^^^^^^^^^^^^^^^^^^^^^^^^^^^^^^^^^^^^^^^
  File "D:\Anaconda\envs\djangoLearn\Lib\site-packages\scrapy\crawler.py", line 452, in _create_crawler
    spidercls = self.spider_loader.load(spidercls)
                ^^^^^^^^^^^^^^^^^^^^^^^^^^^^^^^^^^
  File "D:\Anaconda\envs\djangoLearn\Lib\site-packages\scrapy\spiderloader.py", line 91, in load
    raise KeyError(f"Spider not found: {spider_name}")
KeyError: 'Spider not found: douban_spider'

WARNING 2025-04-05 19:51:32,569 crawler 44800 46972 开始爬取IP
WARNING 2025-04-05 19:51:32,570 crawler 44800 46972 开始爬取IP，类型: IP
ERROR 2025-04-05 19:51:32,597 crawler 44800 46972 爬取IP出错: 'Spider not found: collectip'
ERROR 2025-04-05 19:51:32,599 crawler 44800 46972 Traceback (most recent call last):
  File "D:\Anaconda\envs\djangoLearn\Lib\site-packages\scrapy\spiderloader.py", line 89, in load
    return self._spiders[spider_name]
           ~~~~~~~~~~~~~^^^^^^^^^^^^^
KeyError: 'collectip'

During handling of the above exception, another exception occurred:

Traceback (most recent call last):
  File "D:\python_learn\CollectIp\CollectIp\ip_operator\services\crawler.py", line 422, in start_crawl_ip
    process.crawl('collectip')
  File "D:\Anaconda\envs\djangoLearn\Lib\site-packages\scrapy\crawler.py", line 332, in crawl
    crawler = self.create_crawler(crawler_or_spidercls)
              ^^^^^^^^^^^^^^^^^^^^^^^^^^^^^^^^^^^^^^^^^
  File "D:\Anaconda\envs\djangoLearn\Lib\site-packages\scrapy\crawler.py", line 368, in create_crawler
    return self._create_crawler(crawler_or_spidercls)
           ^^^^^^^^^^^^^^^^^^^^^^^^^^^^^^^^^^^^^^^^^^
  File "D:\Anaconda\envs\djangoLearn\Lib\site-packages\scrapy\crawler.py", line 452, in _create_crawler
    spidercls = self.spider_loader.load(spidercls)
                ^^^^^^^^^^^^^^^^^^^^^^^^^^^^^^^^^^
  File "D:\Anaconda\envs\djangoLearn\Lib\site-packages\scrapy\spiderloader.py", line 91, in load
    raise KeyError(f"Spider not found: {spider_name}")
KeyError: 'Spider not found: collectip'

